<?xml version='1.0'?>
<sdf version='1.7'>
  <model name='Beaumont'>
    <link name='chassis'>
      <pose>0 0 -0 0 -0 0</pose>
      <inertial>
        <mass>23</mass>
        <pose>0 0.13 0.025 0 -0 0</pose>
        <!-- Mass moments of inertia imported from the "Simplified ROV" model in Onshape. Material chosen was Aluminum-->
        <inertia>
          <ixx>0.34673407</ixx>
          <ixy>0</ixy>
          <ixz>0</ixz>
          <iyy>0.2546457474</iyy>
          <iyz>0.000011623</iyz>
          <izz>0.3330063202</izz>
        </inertia>
      </inertial>
      <self_collide>0</self_collide>
      <enable_wind>0</enable_wind>
      <kinematic>0</kinematic>
      <gravity>1</gravity>
      <frame name='chassis_frame'>
        <pose>0 0.5 0 0 -0 0</pose>
      </frame>
      <visual name='assembly_visual'>
        <pose>0 0 0 0 -0 0</pose>
        <geometry>
          <mesh>
            <uri>chassis_assembly.stl</uri>
            <scale>1 1 1</scale>
          </mesh>
        </geometry>
        <material>
        <shader type='pixel'/>
        <ambient>0.2 0.2 0.6 1</ambient>
        <diffuse>0.2 0.2 0.6 1</diffuse>
        <specular>0.2 0.2 0.6 1</specular>
        <emissive>0.2 0.2 0.6 1</emissive>
        </material>
        <transparency>0</transparency>
        <cast_shadows>0</cast_shadows>
      </visual>
      <collision name='assembly_collision'>
        <max_contacts>10</max_contacts>
        <pose>0 0 0 0 -0 0</pose>
        <geometry>
          <mesh>
            <uri>chassis_assembly.stl</uri>
            <scale>1 1 1</scale>
          </mesh>
        </geometry>
      </collision>
      <collision name='electronics_enclosure'>
        <laser_retro>0</laser_retro>
        <max_contacts>10</max_contacts>
        <!-- The enclosure is positioned such that the center of volume is approximately above the center of mass. 
            This required a bit of trial and error.-->
        <pose>0 0.15 0.12 1.5708 0 0</pose>
        <geometry>
          <!-- Note that using Graded Buoyancy instead of Uniform Buoyancy will not work as only boxes and spheres collissions are
              interperted for Graded Buoyancy. -->
          <cylinder>
            <radius>0.083</radius>
            <length>0.3</length>
          </cylinder>
        </geometry>
      </collision>
    </link>
    <model name='left_claw'>
      <pose>0.02 -0.08 -0.02 0 -0 3.14159</pose>
      <link name='left_claw_link'>
        <inertial>
          <pose>-0.0325 0.025 0.01125 0 0 0</pose>
          <mass>0.1</mass>
        </inertial>
        <pose>0 0 -0.1 0 7e-06 0.005444</pose>
        <gravity>1</gravity>
        <self_collide>0</self_collide>
        <kinematic>0</kinematic>
        <enable_wind>0</enable_wind>
        <visual name='claw_hand_visual'>
          <pose>0 0 0 0 3e-06 3e-06</pose>
          <geometry>
            <mesh>
              <uri>claw.stl</uri>
              <scale>1 1 1</scale>
            </mesh>
            </geometry>
            <material>
              <shader type='pixel'/>
              <ambient>0.1 0.1 0.5 1</ambient>
              <diffuse>0.1 0.1 0.5 1</diffuse>
              <specular>0.1 0.1 0.5 1</specular>
              <emissive>0 0 0.5 1</emissive>
            </material>
          <transparency>0</transparency>
          <cast_shadows>0</cast_shadows>
        </visual>
        <collision name='collision_1'>
          <laser_retro>0</laser_retro>
          <max_contacts>10</max_contacts>
          <pose>0 0 0 0 -0 0</pose>
          <geometry>
            <mesh>
                <uri>claw.stl</uri>
              <scale>1 1 1</scale>
            </mesh>
          </geometry>
        </collision>
      </link>
      <static>0</static>
      <allow_auto_disable>1</allow_auto_disable>
    </model>    
    <model name='right_claw'>
      <pose>-0.02 -0.08 -0.2 0 3.14159 3.14159</pose>
      <link name='right_claw_link'>
        <inertial>
          <pose>-0.0325 0.025 0.01125 0 0 0</pose>
          <mass>0.1</mass>
        </inertial>
        <pose>0 0 -0.1 0 7e-06 0.005444</pose>
        <gravity>1</gravity>
        <self_collide>0</self_collide>
        <kinematic>0</kinematic>
        <enable_wind>0</enable_wind>
        <visual name='claw_hand_visual'>
          <pose>0 0 0 0 3e-06 3e-06</pose>
          <geometry>
            <mesh>
              <uri>claw.stl</uri>
              <scale>1 1 1</scale>
            </mesh>
            </geometry>
            <material>
              <shader type='pixel'/>
              <ambient>0.1 0.1 0.5 1</ambient>
              <diffuse>0.1 0.1 0.5 1</diffuse>
              <specular>0.1 0.1 0.5 1</specular>
              <emissive>0 0 0.5 1</emissive>
            </material>
          <transparency>0</transparency>
          <cast_shadows>0</cast_shadows>
        </visual>
        <collision name='collision_1'>
          <laser_retro>0</laser_retro>
          <max_contacts>10</max_contacts>
          <pose>0 0 0 0 -0 0</pose>
          <geometry>
            <mesh>
                <uri>claw.stl</uri>
              <scale>1 1 1</scale>
            </mesh>
          </geometry>
        </collision>
      </link>
      <static>0</static>
      <allow_auto_disable>1</allow_auto_disable>
    </model>
    <joint name='chassis_JOINT_0_1' type='revolute'>
      <parent>chassis</parent>
      <child>right_claw::right_claw_link</child>
      <pose>-0.045 -0.01 0.375 0 -0 0</pose>
      <axis>
        <xyz>0 0 1</xyz>
        <limit>
          <lower>-0.4363</lower>
          <upper>0.4363</upper>
          <effort>-1</effort>
          <velocity>-1</velocity>
        </limit>
        <dynamics>
          <spring_reference>0</spring_reference>
          <spring_stiffness>0</spring_stiffness>
          <damping>0</damping>
          <friction>0</friction>
        </dynamics>
      </axis>
      <physics>
        <ode>
          <limit>
            <cfm>0</cfm>
            <erp>0.2</erp>
          </limit>
          <suspension>
            <cfm>0</cfm>
            <erp>0.2</erp>
          </suspension>
        </ode>
      </physics>
    </joint>
    <joint name='chassis_JOINT_1_1' type='revolute'>
      <parent>chassis</parent>
      <child>left_claw::left_claw_link</child>
      <pose>0.045 -0.01 0.375 0 -0 0</pose>
      <axis>
        <xyz>0 0 1</xyz>
        <limit>
          <lower>-0.4363</lower>
          <upper>0.4363</upper>
          <effort>-1</effort>
          <velocity>-1</velocity>
        </limit>
        <dynamics>
          <spring_reference>0</spring_reference>
          <spring_stiffness>0</spring_stiffness>
          <damping>0</damping>
          <friction>0</friction>
        </dynamics>
      </axis>
      <physics>
        <ode>
          <limit>
            <cfm>0</cfm>
            <erp>0.2</erp>
          </limit>
          <suspension>
            <cfm>0</cfm>
            <erp>0.2</erp>
          </suspension>
        </ode>
      </physics>
    </joint>
    <!-- For Star Top Propeller -->
    <link name="for_star_top_propeller">
      <pose>-0.2 -0.07 0.0875 0.785398 0 0.785398</pose>
      <inertial>
        <pose>0 0 0 0 0 0</pose>
        <mass>0.002</mass>
        <inertia>
          <ixx>0.02179</ixx>
          <ixy>0.000000000008</ixy>
          <ixz>0</ixz>
          <iyy>1.1654</iyy>
          <iyz>0</iyz>
          <izz>1.1654</izz>
        </inertia>
      </inertial>
      <collision name='propeller_collision'>
        <max_contacts>10</max_contacts>
        <pose>0 0 0 0 -0 0</pose>
        <geometry>
          <mesh>
            <uri>propeller.stl</uri>
            <scale>1 1 1</scale>
          </mesh>
        </geometry>
      </collision>
      <visual name='propeller_visual'>
        <pose>0 0 0 0 -0 0</pose>
        <geometry>
          <mesh>
            <uri>propeller.stl</uri>
            <scale>1 1 1</scale>
          </mesh>
        </geometry>
        <material>
        <shader type='pixel'/>
        <ambient>0 0.4 1 1</ambient>
        <diffuse>0 0.4 1 1</diffuse>
        <specular>0 0.4 1 1</specular>
        <emissive>0 0.4 1 1</emissive>
        </material>
        <transparency>0</transparency>
        <cast_shadows>0</cast_shadows>
      </visual>
    </link>
    <joint name='for_star_top_propeller_joint' type='revolute'>
      <parent>chassis</parent>
      <child>for_star_top_propeller</child>
      <pose relative_to="__model__">-0.2 -0.07 0.0875 0.785398 0 0.785398</pose>
      <axis>
        <xyz>0 0 1</xyz>
      </axis>
    </joint>
    <!-- For Port Top Propeller -->
    <link name="for_port_top_propeller">
      <pose>0.2 -0.07 0.0875 5.49778 0 2.35619</pose>
      <inertial>
        <pose>0 0 0 0 0 0</pose>
        <mass>0.002</mass>
        <inertia>
          <ixx>0.02179</ixx>
          <ixy>0.000000000008</ixy>
          <ixz>0</ixz>
          <iyy>1.1654</iyy>
          <iyz>0</iyz>
          <izz>1.1654</izz>
        </inertia>
      </inertial>
      <collision name='propeller_collision'>
        <max_contacts>10</max_contacts>
        <pose>0 0 0 0 -0 0</pose>
        <geometry>
          <mesh>
            <uri>propeller.stl</uri>
            <scale>1 1 1</scale>
          </mesh>
        </geometry>
      </collision>
      <visual name='propeller_visual'>
        <pose>0 0 0 0 -0 0</pose>
        <geometry>
          <mesh>
            <uri>propeller.stl</uri>
            <scale>1 1 1</scale>
          </mesh>
        </geometry>
        <material>
        <shader type='pixel'/>
        <ambient>0 0.4 1 1</ambient>
        <diffuse>0 0.4 1 1</diffuse>
        <specular>0 0.4 1 1</specular>
        <emissive>0 0.4 1 1</emissive>
        </material>
        <transparency>0</transparency>
        <cast_shadows>0</cast_shadows>
      </visual>
    </link>
    <joint name='for_port_top_propeller_joint' type='revolute'>
      <parent>chassis</parent>
      <child>for_port_top_propeller</child>
      <pose relative_to="__model__">0.2 -0.07 0.0875 5.49778 0 2.35619</pose>
      <axis>
        <xyz>0 0 1</xyz>
      </axis>
    </joint>
    <!-- For Star Bot Propeller -->
    <link name="for_star_bot_propeller">
      <pose>-0.2 -0.07 -0.0875 2.356193 0 0.785398</pose>
      <inertial>
        <pose>0 0 0 0 0 0</pose>
        <mass>0.002</mass>
        <inertia>
          <ixx>0.02179</ixx>
          <ixy>0.000000000008</ixy>
          <ixz>0</ixz>
          <iyy>1.1654</iyy>
          <iyz>0</iyz>
          <izz>1.1654</izz>
        </inertia>
      </inertial>
      <collision name='propeller_collision'>
        <max_contacts>10</max_contacts>
        <pose>0 0 0 0 -0 0</pose>
        <geometry>
          <mesh>
            <uri>propeller.stl</uri>
            <scale>1 1 1</scale>
          </mesh>
        </geometry>
      </collision>
      <visual name='propeller_visual'>
        <pose>0 0 0 0 -0 0</pose>
        <geometry>
          <mesh>
            <uri>propeller.stl</uri>
            <scale>1 1 1</scale>
          </mesh>
        </geometry>
        <material>
        <shader type='pixel'/>
        <ambient>0 0.4 1 1</ambient>
        <diffuse>0 0.4 1 1</diffuse>
        <specular>0 0.4 1 1</specular>
        <emissive>0 0.4 1 1</emissive>
        </material>
        <transparency>0</transparency>
        <cast_shadows>0</cast_shadows>
      </visual>
    </link>
    <joint name='for_star_bot_propeller_joint' type='revolute'>
      <parent>chassis</parent>
      <child>for_star_bot_propeller</child>
      <pose relative_to="__model__">-0.2 -0.07 -0.0875 2.356193 0 0.785398</pose>
      <axis>
        <xyz>0 0 1</xyz>
      </axis>
    </joint>
    <!-- For Port Bot Propeller -->
    <link name="for_port_bot_propeller">
      <pose>0.2 -0.07 -0.0875 3.926985 0 2.35619</pose>
      <inertial>
        <pose>0 0 0 0 0 0</pose>
        <mass>0.002</mass>
        <inertia>
          <ixx>0.02179</ixx>
          <ixy>0.000000000008</ixy>
          <ixz>0</ixz>
          <iyy>1.1654</iyy>
          <iyz>0</iyz>
          <izz>1.1654</izz>
        </inertia>
      </inertial>
      <collision name='propeller_collision'>
        <max_contacts>10</max_contacts>
        <pose>0 0 0 0 -0 0</pose>
        <geometry>
          <mesh>
            <uri>propeller.stl</uri>
            <scale>1 1 1</scale>
          </mesh>
        </geometry>
      </collision>
      <visual name='propeller_visual'>
        <pose>0 0 0 0 -0 0</pose>
        <geometry>
          <mesh>
            <uri>propeller.stl</uri>
            <scale>1 1 1</scale>
          </mesh>
        </geometry>
        <material>
        <shader type='pixel'/>
        <ambient>0 0.4 1 1</ambient>
        <diffuse>0 0.4 1 1</diffuse>
        <specular>0 0.4 1 1</specular>
        <emissive>0 0.4 1 1</emissive>
        </material>
        <transparency>0</transparency>
        <cast_shadows>0</cast_shadows>
      </visual>
    </link>
    <joint name='for_port_bot_propeller_joint' type='revolute'>
      <parent>chassis</parent>
      <child>for_port_bot_propeller</child>
      <pose relative_to="__model__">0.2 -0.07 -0.0875 3.926985 0 2.35619</pose>
      <axis>
        <xyz>0 0 1</xyz>
      </axis>
    </joint>
    <!-- Aft Star Top Propeller -->
    <link name="aft_star_top_propeller">
      <pose>-0.2 0.365 0.0875 0.785398 0 2.356193</pose>
      <inertial>
        <pose>0 0 0 0 0 0</pose>
        <mass>0.002</mass>
        <inertia>
          <ixx>0.02179</ixx>
          <ixy>0.000000000008</ixy>
          <ixz>0</ixz>
          <iyy>1.1654</iyy>
          <iyz>0</iyz>
          <izz>1.1654</izz>
        </inertia>
      </inertial>
      <collision name='propeller_collision'>
        <max_contacts>10</max_contacts>
        <pose>0 0 0 0 -0 0</pose>
        <geometry>
          <mesh>
            <uri>propeller.stl</uri>
            <scale>1 1 1</scale>
          </mesh>
        </geometry>
      </collision>
      <visual name='propeller_visual'>
        <pose>0 0 0 0 -0 0</pose>
        <geometry>
          <mesh>
            <uri>propeller.stl</uri>
            <scale>1 1 1</scale>
          </mesh>
        </geometry>
        <material>
        <shader type='pixel'/>
        <ambient>0 0.4 1 1</ambient>
        <diffuse>0 0.4 1 1</diffuse>
        <specular>0 0.4 1 1</specular>
        <emissive>0 0.4 1 1</emissive>
        </material>
        <transparency>0</transparency>
        <cast_shadows>0</cast_shadows>
      </visual>
    </link>
    <joint name='aft_star_top_propeller_joint' type='revolute'>
      <parent>chassis</parent>
      <child>aft_star_top_propeller</child>
      <pose relative_to="__model__">-0.2 0.365 0.0875 0.785398 0 2.356193</pose>
      <axis>
        <xyz>0 0 1</xyz>
      </axis>
    </joint>
    <!-- Aft Port Top Propeller -->
    <link name="aft_port_top_propeller">
      <pose>0.2 0.365 0.0875 5.49778 0 0.785398</pose>
      <inertial>
        <pose>0 0 0 0 0 0</pose>
        <mass>0.002</mass>
        <inertia>
          <ixx>0.02179</ixx>
          <ixy>0.000000000008</ixy>
          <ixz>0</ixz>
          <iyy>1.1654</iyy>
          <iyz>0</iyz>
          <izz>1.1654</izz>
        </inertia>
      </inertial>
      <collision name='propeller_collision'>
        <max_contacts>10</max_contacts>
        <pose>0 0 0 0 -0 0</pose>
        <geometry>
          <mesh>
            <uri>propeller.stl</uri>
            <scale>1 1 1</scale>
          </mesh>
        </geometry>
      </collision>
      <visual name='propeller_visual'>
        <pose>0 0 0 0 -0 0</pose>
        <geometry>
          <mesh>
            <uri>propeller.stl</uri>
            <scale>1 1 1</scale>
          </mesh>
        </geometry>
        <material>
        <shader type='pixel'/>
        <ambient>0 0.4 1 1</ambient>
        <diffuse>0 0.4 1 1</diffuse>
        <specular>0 0.4 1 1</specular>
        <emissive>0 0.4 1 1</emissive>
        </material>
        <transparency>0</transparency>
        <cast_shadows>0</cast_shadows>
      </visual>
    </link>
    <joint name='aft_port_top_propeller_joint' type='revolute'>
      <parent>chassis</parent>
      <child>aft_port_top_propeller</child>
      <pose relative_to="__model__">0.2 0.365 0.0875 5.49778 0 0.785398</pose>
      <axis>
        <xyz>0 0 1</xyz>
      </axis>
    </joint>
    <!-- Aft Star Bot Propeller -->
    <link name="aft_star_bot_propeller">
      <pose>-0.2 0.365 -0.0875 2.356193 0 2.356193</pose>
      <inertial>
        <pose>0 0 0 0 0 0</pose>
        <mass>0.002</mass>
        <inertia>
          <ixx>0.02179</ixx>
          <ixy>0.000000000008</ixy>
          <ixz>0</ixz>
          <iyy>1.1654</iyy>
          <iyz>0</iyz>
          <izz>1.1654</izz>
        </inertia>
      </inertial>
      <collision name='propeller_collision'>
        <max_contacts>10</max_contacts>
        <pose>0 0 0 0 -0 0</pose>
        <geometry>
          <mesh>
            <uri>propeller.stl</uri>
            <scale>1 1 1</scale>
          </mesh>
        </geometry>
      </collision>
      <visual name='propeller_visual'>
        <pose>0 0 0 0 -0 0</pose>
        <geometry>
          <mesh>
            <uri>propeller.stl</uri>
            <scale>1 1 1</scale>
          </mesh>
        </geometry>
        <material>
        <shader type='pixel'/>
        <ambient>0 0.4 1 1</ambient>
        <diffuse>0 0.4 1 1</diffuse>
        <specular>0 0.4 1 1</specular>
        <emissive>0 0.4 1 1</emissive>
        </material>
        <transparency>0</transparency>
        <cast_shadows>0</cast_shadows>
      </visual>
    </link>
    <joint name='aft_star_bot_propeller_joint' type='revolute'>
      <parent>chassis</parent>
      <child>aft_star_bot_propeller</child>
      <pose relative_to="__model__">-0.2 0.365 -0.0875 2.356193 0 2.356193</pose>
      <axis>
        <xyz>0 0 1</xyz>
      </axis>
    </joint>
    <!-- Aft Port Bot Propeller -->
    <link name="aft_port_bot_propeller">
      <pose>0.2 0.365 -0.0875 3.926988 0 0.785398</pose>
      <inertial>
        <pose>0 0 0 0 0 0</pose>
        <mass>0.002</mass>
        <inertia>
          <ixx>0.02179</ixx>
          <ixy>0.000000000008</ixy>
          <ixz>0</ixz>
          <iyy>1.1654</iyy>
          <iyz>0</iyz>
          <izz>1.1654</izz>
        </inertia>
      </inertial>
      <collision name='propeller_collision'>
        <max_contacts>10</max_contacts>
        <pose>0 0 0 0 -0 0</pose>
        <geometry>
          <mesh>
            <uri>propeller.stl</uri>
            <scale>1 1 1</scale>
          </mesh>
        </geometry>
      </collision>
      <visual name='propeller_visual'>
        <pose>0 0 0 0 -0 0</pose>
        <geometry>
          <mesh>
            <uri>propeller.stl</uri>
            <scale>1 1 1</scale>
          </mesh>
        </geometry>
        <material>
        <shader type='pixel'/>
        <ambient>0 0.4 1 1</ambient>
        <diffuse>0 0.4 1 1</diffuse>
        <specular>0 0.4 1 1</specular>
        <emissive>0 0.4 1 1</emissive>
        </material>
        <transparency>0</transparency>
        <cast_shadows>0</cast_shadows>
      </visual>
    </link>
    <joint name='aft_port_bot_propeller_joint' type='revolute'>
      <parent>chassis</parent>
      <child>aft_port_bot_propeller</child>
      <pose relative_to="__model__">0.2 0.365 -0.0875 3.926988 0 0.785398</pose>
      <axis>
        <xyz>0 0 1</xyz>
      </axis>
    </joint>
    <static>0</static>
    <self_collide>0</self_collide>
    <allow_auto_disable>1</allow_auto_disable>
  </model>
</sdf>
